Workbook

Sheet Resumen
A1: Línea base de costos — CRM Predictivo y Retención Postventa · Essenza SPA
A2: Gestión de Proyectos TI · UNTELS · Dominio de desempeño de Finanzas (Guía PMBOK® 8) · Proyecto del 15/09/2026 al 15/01/2027
A4: Concepto | B4: Monto (S/) | C4: Cómo se calcula
A5: Mano de obra del equipo | B5: =Paquetes!M42 -> 35096 | C5: Σ horas por rol × tarifa por hora (hoja Paquetes)
A6: Costos directos no laborales | B6: ='No laborales'!C13 -> 2210 | C6: Materiales, equipos y gastos (hoja No laborales)
A7: Ajuste por estimación PERT | B7: =Paquetes!V42-Paquetes!O42 -> 232 | C7: E = (O + 4M + P) / 6 en 3 paquetes inciertos
A8: Costo de los paquetes de trabajo | B8: =Presupuesto!B13 -> 37538 | C8: Σ estimación final de los 36 paquetes
A9: Reserva de contingencia | B9: =Presupuesto!B14 -> 2525 | C9: Σ VME = probabilidad × impacto (hoja Riesgos)
A10: Línea base de costos (BAC) | B10: =Presupuesto!B15 -> 40063 | C10: Paquetes + contingencia
A11: Reserva de gestión | B11: =Presupuesto!B17 -> 2003 | C11: 5 % de la línea base (editable en Presupuesto)
A12: PRESUPUESTO TOTAL DEL PROYECTO | B12: =Presupuesto!B18 -> 42066 | C12: Línea base + reserva de gestión
A13: Presupuesto autorizado en el acta de constitución | B13: =Presupuesto!B20 -> 42200 | C13: Orden de magnitud aprobado en el acta de constitución
A14: Holgura frente al acta | B14: =Presupuesto!B21 -> 134 | C14: Autorizado − presupuesto del proyecto
A16: Leyenda
A17: Texto azul | B17: Dato de entrada: puedes cambiarlo y todo se recalcula
A18: Texto verde | B18: Vínculo a otra hoja
A19: Texto negro | B19: Fórmula calculada
A20: Fondo amarillo | B20: Supuesto clave a validar con el docente o la patrocinadora
A22: Hojas
A23: Tarifas | B23: Sueldos y tarifa por hora de cada rol
A24: Paquetes | B24: Estimación bottom-up de los 36 paquetes, con PERT
A25: No laborales | B25: Gastos directos que no son horas
A26: Riesgos | B26: Reserva de contingencia por VME
A27: Presupuesto | B27: Agregación por entregable y reservas
A28: Curva S | B28: Valor planificado acumulado por semana
A29: Valor ganado | B29: Fórmulas EVM con un ejemplo al corte H2
A30: Viabilidad | B30: VAN, ROI y periodo de recuperación

Sheet Tarifas
A1: Tarifas por rol
A2: Tarifa por hora = sueldo mensual ÷ horas laborables al mes. Celdas en azul = datos de entrada editables.
A4: Horas laborables por mes | C4: 160
A6: Código | B6: Rol | C6: Sueldo mensual (S/) | D6: Tarifa por hora (S/) | E6: Horas asignadas | F6: Costo de mano de obra (S/) | G6: % del costo laboral
A7: DP | B7: Director del proyecto | C7: 4800 | D7: =C7/$C$4 -> 30 | E7: =Paquetes!D42 -> 305.6 | F7: =D7*E7 -> 9168 | G7: =IF($F$15=0,0,F7/$F$15) -> 0.26122635
A8: AF | B8: Analista funcional | C8: 3200 | D8: =C8/$C$4 -> 20 | E8: =Paquetes!E42 -> 128 | F8: =D8*E8 -> 2560 | G8: =IF($F$15=0,0,F8/$F$15) -> 0.072942786
A9: CD | B9: Científico de datos | C9: 4000 | D9: =C9/$C$4 -> 25 | E9: =Paquetes!F42 -> 208 | F9: =D9*E9 -> 5200 | G9: =IF($F$15=0,0,F9/$F$15) -> 0.14816503
A10: DB | B10: Desarrollador backend | C10: 3520 | D10: =C10/$C$4 -> 22 | E10: =Paquetes!G42 -> 344 | F10: =D10*E10 -> 7568 | G10: =IF($F$15=0,0,F10/$F$15) -> 0.21563711
A11: DF | B11: Desarrollador frontend | C11: 3200 | D11: =C11/$C$4 -> 20 | E11: =Paquetes!H42 -> 304 | F11: =D11*E11 -> 6080 | G11: =IF($F$15=0,0,F11/$F$15) -> 0.17323912
A12: QA | B12: QA y capacitación | C12: 2560 | D12: =C12/$C$4 -> 16 | E12: =Paquetes!I42 -> 240 | F12: =D12*E12 -> 3840 | G12: =IF($F$15=0,0,F12/$F$15) -> 0.10941418
A13: ADM | B13: Administradora (interno) | C13: 2400 | D13: =C13/$C$4 -> 15 | E13: =Paquetes!J42 -> 32 | F13: =D13*E13 -> 480 | G13: =IF($F$15=0,0,F13/$F$15) -> 0.013676772
A14: PAT | B14: Dueña – patrocinadora (interno) | C14: 4000 | D14: =C14/$C$4 -> 25 | E14: =Paquetes!K42 -> 8 | F14: =D14*E14 -> 200 | G14: =IF($F$15=0,0,F14/$F$15) -> 0.0056986551
A15: Total | E15: =SUM(E7:E14) -> 1569.6 | F15: =SUM(F7:F14) -> 35096 | G15: =SUM(G7:G14) -> 1
A17: Fuente de los sueldos: valores de referencia del mercado de Lima para perfiles TI junior (supuesto del equipo, no cotización). Los roles internos (administradora y dueña) se valorizan con su costo de oportunidad.

Sheet No laborales
A1: Costos directos no laborales
A2: Materiales, equipos y gastos que no son horas del equipo. Montos en azul = entrada.
A4: Paquete EDT | B4: Descripción | C4: Monto (S/)
A5: EDT-1.1.01 | B5: Impresión de actas y documentos del proyecto | C5: 120
A6: EDT-1.1.03 | B6: Movilidad del equipo a las reuniones en el spa | C6: 480
A7: EDT-1.2.01 | B7: Materiales para entrevistas y talleres de levantamiento | C7: 80
A8: EDT-1.8.01 | B8: UPS para la PC de recepción | C8: 380
A9: EDT-1.8.01 | B9: Disco externo de 1 TB para respaldos | C9: 260
A10: EDT-1.8.02 | B10: Impresión de manuales y guía rápida | C10: 180
A11: EDT-1.8.03 | B11: Refrigerios para los 3 talleres de capacitación | C11: 210
A12: EDT-1.8.04 | B12: Fondo de beneficios para el piloto de retención | C12: 500
A13: Total | C13: =SUM(C5:C12) -> 2210
A15: Fuente: precios estimados de mercado (supuesto del equipo). Para agregar un gasto, inserta una fila dentro del rango y escribe el código del paquete.

Sheet Paquetes
A1: Estimación de costos por paquete de trabajo (bottom-up)
A2: Mano de obra = Σ (horas del rol × tarifa). Base = mano de obra + no laborales. PERT: E = (O + 4M + P) / 6 ; σ = (P − O) / 6.
C4: Tarifa por hora (S/) → | D4: =Tarifas!D7 -> 30 | E4: =Tarifas!D8 -> 20 | F4: =Tarifas!D9 -> 25 | G4: =Tarifas!D10 -> 22 | H4: =Tarifas!D11 -> 20 | I4: =Tarifas!D12 -> 16 | J4: =Tarifas!D13 -> 15 | K4: =Tarifas!D14 -> 25
A5: Paquete EDT | B5: Entregable | C5: Nombre del paquete | D5: Director del proyecto (h) | E5: Analista funcional (h) | F5: Científico de datos (h) | G5: Desarrollador backend (h) | H5: Desarrollador frontend (h) | I5: QA y capacitación (h) | J5: Administradora (h) | K5: Dueña (h) | L5: Horas totales | M5: Mano de obra (S/) | N5: No laborales (S/) | O5: Costo base M (S/) | P5: Factor optimista | Q5: Factor pesimista | R5: Optimista O (S/) | S5: Pesimista P (S/) | T5: PERT E (S/) | U5: σ (S/) | V5: Estimación final (S/)
A6: EDT-1.1.01 | B6: 1.1 Gestión del proyecto | C6: Acta de constitución y lanzamiento | D6: 24 | L6: =SUM(D6:K6) -> 24 | M6: =ROUND(SUMPRODUCT(D6:K6,$D$4:$K$4),0) -> 720 | N6: =SUMIF('No laborales'!$A$5:$A$12,A6,'No laborales'!$C$5:$C$12) -> 120 | O6: =M6+N6 -> 840 | R6: =IF(P6="","",O6*P6) | S6: =IF(Q6="","",O6*Q6) | T6: =IF(P6="","",(R6+4*O6+S6)/6) | U6: =IF(P6="","",(S6-R6)/6) | V6: =IF(P6="",O6,ROUND(T6,0)) -> 840
A7: EDT-1.1.02 | B7: 1.1 Gestión del proyecto | C7: Plan para la dirección del proyecto | D7: 32 | L7: =SUM(D7:K7) -> 32 | M7: =ROUND(SUMPRODUCT(D7:K7,$D$4:$K$4),0) -> 960 | N7: =SUMIF('No laborales'!$A$5:$A$12,A7,'No laborales'!$C$5:$C$12) -> 0 | O7: =M7+N7 -> 960 | R7: =IF(P7="","",O7*P7) | S7: =IF(Q7="","",O7*Q7) | T7: =IF(P7="","",(R7+4*O7+S7)/6) | U7: =IF(P7="","",(S7-R7)/6) | V7: =IF(P7="",O7,ROUND(T7,0)) -> 960
A8: EDT-1.1.03 | B8: 1.1 Gestión del proyecto | C8: Seguimiento y control | D8: 201.6 | L8: =SUM(D8:K8) -> 201.6 | M8: =ROUND(SUMPRODUCT(D8:K8,$D$4:$K$4),0) -> 6048 | N8: =SUMIF('No laborales'!$A$5:$A$12,A8,'No laborales'!$C$5:$C$12) -> 480 | O8: =M8+N8 -> 6528 | R8: =IF(P8="","",O8*P8) | S8: =IF(Q8="","",O8*Q8) | T8: =IF(P8="","",(R8+4*O8+S8)/6) | U8: =IF(P8="","",(S8-R8)/6) | V8: =IF(P8="",O8,ROUND(T8,0)) -> 6528
A9: EDT-1.1.04 | B9: 1.1 Gestión del proyecto | C9: Cierre del proyecto | D9: 24 | L9: =SUM(D9:K9) -> 24 | M9: =ROUND(SUMPRODUCT(D9:K9,$D$4:$K$4),0) -> 720 | N9: =SUMIF('No laborales'!$A$5:$A$12,A9,'No laborales'!$C$5:$C$12) -> 0 | O9: =M9+N9 -> 720 | R9: =IF(P9="","",O9*P9) | S9: =IF(Q9="","",O9*Q9) | T9: =IF(P9="","",(R9+4*O9+S9)/6) | U9: =IF(P9="","",(S9-R9)/6) | V9: =IF(P9="",O9,ROUND(T9,0)) -> 720
A10: EDT-1.2.01 | B10: 1.2 Análisis y diseño | C10: Levantamiento AS-IS y requisitos | E10: 32 | J10: 8 | L10: =SUM(D10:K10) -> 40 | M10: =ROUND(SUMPRODUCT(D10:K10,$D$4:$K$4),0) -> 760 | N10: =SUMIF('No laborales'!$A$5:$A$12,A10,'No laborales'!$C$5:$C$12) -> 80 | O10: =M10+N10 -> 840 | R10: =IF(P10="","",O10*P10) | S10: =IF(Q10="","",O10*Q10) | T10: =IF(P10="","",(R10+4*O10+S10)/6) | U10: =IF(P10="","",(S10-R10)/6) | V10: =IF(P10="",O10,ROUND(T10,0)) -> 840
A11: EDT-1.2.02 | B11: 1.2 Análisis y diseño | C11: Especificación de requisitos y trazabilidad | E11: 32 | L11: =SUM(D11:K11) -> 32 | M11: =ROUND(SUMPRODUCT(D11:K11,$D$4:$K$4),0) -> 640 | N11: =SUMIF('No laborales'!$A$5:$A$12,A11,'No laborales'!$C$5:$C$12) -> 0 | O11: =M11+N11 -> 640 | R11: =IF(P11="","",O11*P11) | S11: =IF(Q11="","",O11*Q11) | T11: =IF(P11="","",(R11+4*O11+S11)/6) | U11: =IF(P11="","",(S11-R11)/6) | V11: =IF(P11="",O11,ROUND(T11,0)) -> 640
A12: EDT-1.2.03 | B12: 1.2 Análisis y diseño | C12: Arquitectura y modelo de datos | G12: 32 | L12: =SUM(D12:K12) -> 32 | M12: =ROUND(SUMPRODUCT(D12:K12,$D$4:$K$4),0) -> 704 | N12: =SUMIF('No laborales'!$A$5:$A$12,A12,'No laborales'!$C$5:$C$12) -> 0 | O12: =M12+N12 -> 704 | R12: =IF(P12="","",O12*P12) | S12: =IF(Q12="","",O12*Q12) | T12: =IF(P12="","",(R12+4*O12+S12)/6) | U12: =IF(P12="","",(S12-R12)/6) | V12: =IF(P12="",O12,ROUND(T12,0)) -> 704
A13: EDT-1.2.04 | B13: 1.2 Análisis y diseño | C13: Prototipo de interfaz (UX/UI) | H13: 32 | L13: =SUM(D13:K13) -> 32 | M13: =ROUND(SUMPRODUCT(D13:K13,$D$4:$K$4),0) -> 640 | N13: =SUMIF('No laborales'!$A$5:$A$12,A13,'No laborales'!$C$5:$C$12) -> 0 | O13: =M13+N13 -> 640 | R13: =IF(P13="","",O13*P13) | S13: =IF(Q13="","",O13*Q13) | T13: =IF(P13="","",(R13+4*O13+S13)/6) | U13: =IF(P13="","",(S13-R13)/6) | V13: =IF(P13="",O13,ROUND(T13,0)) -> 640
A14: EDT-1.2.05 | B14: 1.2 Análisis y diseño | C14: Reglas de negocio de retención | E14: 24 | L14: =SUM(D14:K14) -> 24 | M14: =ROUND(SUMPRODUCT(D14:K14,$D$4:$K$4),0) -> 480 | N14: =SUMIF('No laborales'!$A$5:$A$12,A14,'No laborales'!$C$5:$C$12) -> 0 | O14: =M14+N14 -> 480 | R14: =IF(P14="","",O14*P14) | S14: =IF(Q14="","",O14*Q14) | T14: =IF(P14="","",(R14+4*O14+S14)/6) | U14: =IF(P14="","",(S14-R14)/6) | V14: =IF(P14="",O14,ROUND(T14,0)) -> 480
A15: EDT-1.3.01 | B15: 1.3 Datos y modelo predictivo | C15: Registro operacional Excel normalizado | F15: 24 | L15: =SUM(D15:K15) -> 24 | M15: =ROUND(SUMPRODUCT(D15:K15,$D$4:$K$4),0) -> 600 | N15: =SUMIF('No laborales'!$A$5:$A$12,A15,'No laborales'!$C$5:$C$12) -> 0 | O15: =M15+N15 -> 600 | R15: =IF(P15="","",O15*P15) | S15: =IF(Q15="","",O15*Q15) | T15: =IF(P15="","",(R15+4*O15+S15)/6) | U15: =IF(P15="","",(S15-R15)/6) | V15: =IF(P15="",O15,ROUND(T15,0)) -> 600
A16: EDT-1.3.02 | B16: 1.3 Datos y modelo predictivo | C16: Dataset depurado y calidad de datos | F16: 32 | L16: =SUM(D16:K16) -> 32 | M16: =ROUND(SUMPRODUCT(D16:K16,$D$4:$K$4),0) -> 800 | N16: =SUMIF('No laborales'!$A$5:$A$12,A16,'No laborales'!$C$5:$C$12) -> 0 | O16: =M16+N16 -> 800 | R16: =IF(P16="","",O16*P16) | S16: =IF(Q16="","",O16*Q16) | T16: =IF(P16="","",(R16+4*O16+S16)/6) | U16: =IF(P16="","",(S16-R16)/6) | V16: =IF(P16="",O16,ROUND(T16,0)) -> 800
A17: EDT-1.3.03 | B17: 1.3 Datos y modelo predictivo | C17: Ingeniería de características | F17: 40 | L17: =SUM(D17:K17) -> 40 | M17: =ROUND(SUMPRODUCT(D17:K17,$D$4:$K$4),0) -> 1000 | N17: =SUMIF('No laborales'!$A$5:$A$12,A17,'No laborales'!$C$5:$C$12) -> 0 | O17: =M17+N17 -> 1000 | R17: =IF(P17="","",O17*P17) | S17: =IF(Q17="","",O17*Q17) | T17: =IF(P17="","",(R17+4*O17+S17)/6) | U17: =IF(P17="","",(S17-R17)/6) | V17: =IF(P17="",O17,ROUND(T17,0)) -> 1000
A18: EDT-1.3.04 | B18: 1.3 Datos y modelo predictivo | C18: Modelo XGBoost entrenado | F18: 56 | L18: =SUM(D18:K18) -> 56 | M18: =ROUND(SUMPRODUCT(D18:K18,$D$4:$K$4),0) -> 1400 | N18: =SUMIF('No laborales'!$A$5:$A$12,A18,'No laborales'!$C$5:$C$12) -> 0 | O18: =M18+N18 -> 1400 | P18: 0.85 | Q18: 1.6 | R18: =IF(P18="","",O18*P18) -> 1190 | S18: =IF(Q18="","",O18*Q18) -> 2240 | T18: =IF(P18="","",(R18+4*O18+S18)/6) -> 1505 | U18: =IF(P18="","",(S18-R18)/6) -> 175 | V18: =IF(P18="",O18,ROUND(T18,0)) -> 1505
A19: EDT-1.3.05 | B19: 1.3 Datos y modelo predictivo | C19: Evaluación, interpretabilidad y empaquetado | F19: 32 | K19: 8 | L19: =SUM(D19:K19) -> 40 | M19: =ROUND(SUMPRODUCT(D19:K19,$D$4:$K$4),0) -> 1000 | N19: =SUMIF('No laborales'!$A$5:$A$12,A19,'No laborales'!$C$5:$C$12) -> 0 | O19: =M19+N19 -> 1000 | R19: =IF(P19="","",O19*P19) | S19: =IF(Q19="","",O19*Q19) | T19: =IF(P19="","",(R19+4*O19+S19)/6) | U19: =IF(P19="","",(S19-R19)/6) | V19: =IF(P19="",O19,ROUND(T19,0)) -> 1000
A20: EDT-1.4.01 | B20: 1.4 Backend e integración | C20: Base de datos SQLite | G20: 24 | L20: =SUM(D20:K20) -> 24 | M20: =ROUND(SUMPRODUCT(D20:K20,$D$4:$K$4),0) -> 528 | N20: =SUMIF('No laborales'!$A$5:$A$12,A20,'No laborales'!$C$5:$C$12) -> 0 | O20: =M20+N20 -> 528 | R20: =IF(P20="","",O20*P20) | S20: =IF(Q20="","",O20*Q20) | T20: =IF(P20="","",(R20+4*O20+S20)/6) | U20: =IF(P20="","",(S20-R20)/6) | V20: =IF(P20="",O20,ROUND(T20,0)) -> 528
A21: EDT-1.4.02 | B21: 1.4 Backend e integración | C21: Lectura y validación del Excel | G21: 24 | L21: =SUM(D21:K21) -> 24 | M21: =ROUND(SUMPRODUCT(D21:K21,$D$4:$K$4),0) -> 528 | N21: =SUMIF('No laborales'!$A$5:$A$12,A21,'No laborales'!$C$5:$C$12) -> 0 | O21: =M21+N21 -> 528 | R21: =IF(P21="","",O21*P21) | S21: =IF(Q21="","",O21*Q21) | T21: =IF(P21="","",(R21+4*O21+S21)/6) | U21: =IF(P21="","",(S21-R21)/6) | V21: =IF(P21="",O21,ROUND(T21,0)) -> 528
A22: EDT-1.4.03 | B22: 1.4 Backend e integración | C22: Sincronización automática | G22: 24 | L22: =SUM(D22:K22) -> 24 | M22: =ROUND(SUMPRODUCT(D22:K22,$D$4:$K$4),0) -> 528 | N22: =SUMIF('No laborales'!$A$5:$A$12,A22,'No laborales'!$C$5:$C$12) -> 0 | O22: =M22+N22 -> 528 | P22: 0.85 | Q22: 1.5 | R22: =IF(P22="","",O22*P22) -> 448.8 | S22: =IF(Q22="","",O22*Q22) -> 792 | T22: =IF(P22="","",(R22+4*O22+S22)/6) -> 558.8 | U22: =IF(P22="","",(S22-R22)/6) -> 57.2 | V22: =IF(P22="",O22,ROUND(T22,0)) -> 559
A23: EDT-1.4.04 | B23: 1.4 Backend e integración | C23: Predicción y alertas | F23: 8 | G23: 32 | L23: =SUM(D23:K23) -> 40 | M23: =ROUND(SUMPRODUCT(D23:K23,$D$4:$K$4),0) -> 904 | N23: =SUMIF('No laborales'!$A$5:$A$12,A23,'No laborales'!$C$5:$C$12) -> 0 | O23: =M23+N23 -> 904 | R23: =IF(P23="","",O23*P23) | S23: =IF(Q23="","",O23*Q23) | T23: =IF(P23="","",(R23+4*O23+S23)/6) | U23: =IF(P23="","",(S23-R23)/6) | V23: =IF(P23="",O23,ROUND(T23,0)) -> 904
A24: EDT-1.4.05 | B24: 1.4 Backend e integración | C24: API REST y autenticación | G24: 48 | L24: =SUM(D24:K24) -> 48 | M24: =ROUND(SUMPRODUCT(D24:K24,$D$4:$K$4),0) -> 1056 | N24: =SUMIF('No laborales'!$A$5:$A$12,A24,'No laborales'!$C$5:$C$12) -> 0 | O24: =M24+N24 -> 1056 | R24: =IF(P24="","",O24*P24) | S24: =IF(Q24="","",O24*Q24) | T24: =IF(P24="","",(R24+4*O24+S24)/6) | U24: =IF(P24="","",(S24-R24)/6) | V24: =IF(P24="",O24,ROUND(T24,0)) -> 1056
A25: EDT-1.5.01 | B25: 1.5 Aplicación web CRM | C25: Inicio de sesión y navegación | H25: 24 | L25: =SUM(D25:K25) -> 24 | M25: =ROUND(SUMPRODUCT(D25:K25,$D$4:$K$4),0) -> 480 | N25: =SUMIF('No laborales'!$A$5:$A$12,A25,'No laborales'!$C$5:$C$12) -> 0 | O25: =M25+N25 -> 480 | R25: =IF(P25="","",O25*P25) | S25: =IF(Q25="","",O25*Q25) | T25: =IF(P25="","",(R25+4*O25+S25)/6) | U25: =IF(P25="","",(S25-R25)/6) | V25: =IF(P25="",O25,ROUND(T25,0)) -> 480
A26: EDT-1.5.02 | B26: 1.5 Aplicación web CRM | C26: Dashboard analítico | H26: 40 | L26: =SUM(D26:K26) -> 40 | M26: =ROUND(SUMPRODUCT(D26:K26,$D$4:$K$4),0) -> 800 | N26: =SUMIF('No laborales'!$A$5:$A$12,A26,'No laborales'!$C$5:$C$12) -> 0 | O26: =M26+N26 -> 800 | R26: =IF(P26="","",O26*P26) | S26: =IF(Q26="","",O26*Q26) | T26: =IF(P26="","",(R26+4*O26+S26)/6) | U26: =IF(P26="","",(S26-R26)/6) | V26: =IF(P26="",O26,ROUND(T26,0)) -> 800
A27: EDT-1.5.03 | B27: 1.5 Aplicación web CRM | C27: Clientes y ficha 360° | H27: 48 | L27: =SUM(D27:K27) -> 48 | M27: =ROUND(SUMPRODUCT(D27:K27,$D$4:$K$4),0) -> 960 | N27: =SUMIF('No laborales'!$A$5:$A$12,A27,'No laborales'!$C$5:$C$12) -> 0 | O27: =M27+N27 -> 960 | R27: =IF(P27="","",O27*P27) | S27: =IF(Q27="","",O27*Q27) | T27: =IF(P27="","",(R27+4*O27+S27)/6) | U27: =IF(P27="","",(S27-R27)/6) | V27: =IF(P27="",O27,ROUND(T27,0)) -> 960
A28: EDT-1.5.04 | B28: 1.5 Aplicación web CRM | C28: Centro de alertas y vistas del sistema | H28: 32 | L28: =SUM(D28:K28) -> 32 | M28: =ROUND(SUMPRODUCT(D28:K28,$D$4:$K$4),0) -> 640 | N28: =SUMIF('No laborales'!$A$5:$A$12,A28,'No laborales'!$C$5:$C$12) -> 0 | O28: =M28+N28 -> 640 | R28: =IF(P28="","",O28*P28) | S28: =IF(Q28="","",O28*Q28) | T28: =IF(P28="","",(R28+4*O28+S28)/6) | U28: =IF(P28="","",(S28-R28)/6) | V28: =IF(P28="",O28,ROUND(T28,0)) -> 640
A29: EDT-1.6.01 | B29: 1.6 Módulo de retención | C29: Modelo de datos de retención | G29: 24 | L29: =SUM(D29:K29) -> 24 | M29: =ROUND(SUMPRODUCT(D29:K29,$D$4:$K$4),0) -> 528 | N29: =SUMIF('No laborales'!$A$5:$A$12,A29,'No laborales'!$C$5:$C$12) -> 0 | O29: =M29+N29 -> 528 | R29: =IF(P29="","",O29*P29) | S29: =IF(Q29="","",O29*Q29) | T29: =IF(P29="","",(R29+4*O29+S29)/6) | U29: =IF(P29="","",(S29-R29)/6) | V29: =IF(P29="",O29,ROUND(T29,0)) -> 528
A30: EDT-1.6.02 | B30: 1.6 Módulo de retención | C30: Motor de casos y recuperación | F30: 16 | G30: 40 | L30: =SUM(D30:K30) -> 56 | M30: =ROUND(SUMPRODUCT(D30:K30,$D$4:$K$4),0) -> 1280 | N30: =SUMIF('No laborales'!$A$5:$A$12,A30,'No laborales'!$C$5:$C$12) -> 0 | O30: =M30+N30 -> 1280 | P30: 0.85 | Q30: 1.6 | R30: =IF(P30="","",O30*P30) -> 1088 | S30: =IF(Q30="","",O30*Q30) -> 2048 | T30: =IF(P30="","",(R30+4*O30+S30)/6) -> 1376 | U30: =IF(P30="","",(S30-R30)/6) -> 160 | V30: =IF(P30="",O30,ROUND(T30,0)) -> 1376
A31: EDT-1.6.03 | B31: 1.6 Módulo de retención | C31: Centro de Retención | H31: 40 | L31: =SUM(D31:K31) -> 40 | M31: =ROUND(SUMPRODUCT(D31:K31,$D$4:$K$4),0) -> 800 | N31: =SUMIF('No laborales'!$A$5:$A$12,A31,'No laborales'!$C$5:$C$12) -> 0 | O31: =M31+N31 -> 800 | R31: =IF(P31="","",O31*P31) | S31: =IF(Q31="","",O31*Q31) | T31: =IF(P31="","",(R31+4*O31+S31)/6) | U31: =IF(P31="","",(S31-R31)/6) | V31: =IF(P31="",O31,ROUND(T31,0)) -> 800
A32: EDT-1.6.04 | B32: 1.6 Módulo de retención | C32: Contacto por WhatsApp | H32: 24 | L32: =SUM(D32:K32) -> 24 | M32: =ROUND(SUMPRODUCT(D32:K32,$D$4:$K$4),0) -> 480 | N32: =SUMIF('No laborales'!$A$5:$A$12,A32,'No laborales'!$C$5:$C$12) -> 0 | O32: =M32+N32 -> 480 | R32: =IF(P32="","",O32*P32) | S32: =IF(Q32="","",O32*Q32) | T32: =IF(P32="","",(R32+4*O32+S32)/6) | U32: =IF(P32="","",(S32-R32)/6) | V32: =IF(P32="",O32,ROUND(T32,0)) -> 480
A33: EDT-1.7.01 | B33: 1.7 Pruebas y calidad | C33: Plan y casos de prueba | I33: 32 | L33: =SUM(D33:K33) -> 32 | M33: =ROUND(SUMPRODUCT(D33:K33,$D$4:$K$4),0) -> 512 | N33: =SUMIF('No laborales'!$A$5:$A$12,A33,'No laborales'!$C$5:$C$12) -> 0 | O33: =M33+N33 -> 512 | R33: =IF(P33="","",O33*P33) | S33: =IF(Q33="","",O33*Q33) | T33: =IF(P33="","",(R33+4*O33+S33)/6) | U33: =IF(P33="","",(S33-R33)/6) | V33: =IF(P33="",O33,ROUND(T33,0)) -> 512
A34: EDT-1.7.02 | B34: 1.7 Pruebas y calidad | C34: Pruebas unitarias e integración | I34: 56 | L34: =SUM(D34:K34) -> 56 | M34: =ROUND(SUMPRODUCT(D34:K34,$D$4:$K$4),0) -> 896 | N34: =SUMIF('No laborales'!$A$5:$A$12,A34,'No laborales'!$C$5:$C$12) -> 0 | O34: =M34+N34 -> 896 | R34: =IF(P34="","",O34*P34) | S34: =IF(Q34="","",O34*Q34) | T34: =IF(P34="","",(R34+4*O34+S34)/6) | U34: =IF(P34="","",(S34-R34)/6) | V34: =IF(P34="",O34,ROUND(T34,0)) -> 896
A35: EDT-1.7.03 | B35: 1.7 Pruebas y calidad | C35: Pruebas integrales del sistema | I35: 32 | L35: =SUM(D35:K35) -> 32 | M35: =ROUND(SUMPRODUCT(D35:K35,$D$4:$K$4),0) -> 512 | N35: =SUMIF('No laborales'!$A$5:$A$12,A35,'No laborales'!$C$5:$C$12) -> 0 | O35: =M35+N35 -> 512 | R35: =IF(P35="","",O35*P35) | S35: =IF(Q35="","",O35*Q35) | T35: =IF(P35="","",(R35+4*O35+S35)/6) | U35: =IF(P35="","",(S35-R35)/6) | V35: =IF(P35="",O35,ROUND(T35,0)) -> 512
A36: EDT-1.7.04 | B36: 1.7 Pruebas y calidad | C36: Pruebas de aceptación (UAT) | I36: 24 | J36: 16 | L36: =SUM(D36:K36) -> 40 | M36: =ROUND(SUMPRODUCT(D36:K36,$D$4:$K$4),0) -> 624 | N36: =SUMIF('No laborales'!$A$5:$A$12,A36,'No laborales'!$C$5:$C$12) -> 0 | O36: =M36+N36 -> 624 | R36: =IF(P36="","",O36*P36) | S36: =IF(Q36="","",O36*Q36) | T36: =IF(P36="","",(R36+4*O36+S36)/6) | U36: =IF(P36="","",(S36-R36)/6) | V36: =IF(P36="",O36,ROUND(T36,0)) -> 624
A37: EDT-1.8.01 | B37: 1.8 Despliegue y transición | C37: Entorno de producción y respaldo | G37: 32 | L37: =SUM(D37:K37) -> 32 | M37: =ROUND(SUMPRODUCT(D37:K37,$D$4:$K$4),0) -> 704 | N37: =SUMIF('No laborales'!$A$5:$A$12,A37,'No laborales'!$C$5:$C$12) -> 640 | O37: =M37+N37 -> 1344 | R37: =IF(P37="","",O37*P37) | S37: =IF(Q37="","",O37*Q37) | T37: =IF(P37="","",(R37+4*O37+S37)/6) | U37: =IF(P37="","",(S37-R37)/6) | V37: =IF(P37="",O37,ROUND(T37,0)) -> 1344
A38: EDT-1.8.02 | B38: 1.8 Despliegue y transición | C38: Documentación y manuales | E38: 32 | L38: =SUM(D38:K38) -> 32 | M38: =ROUND(SUMPRODUCT(D38:K38,$D$4:$K$4),0) -> 640 | N38: =SUMIF('No laborales'!$A$5:$A$12,A38,'No laborales'!$C$5:$C$12) -> 180 | O38: =M38+N38 -> 820 | R38: =IF(P38="","",O38*P38) | S38: =IF(Q38="","",O38*Q38) | T38: =IF(P38="","",(R38+4*O38+S38)/6) | U38: =IF(P38="","",(S38-R38)/6) | V38: =IF(P38="",O38,ROUND(T38,0)) -> 820
A39: EDT-1.8.03 | B39: 1.8 Despliegue y transición | C39: Capacitación por rol | I39: 32 | J39: 8 | L39: =SUM(D39:K39) -> 40 | M39: =ROUND(SUMPRODUCT(D39:K39,$D$4:$K$4),0) -> 632 | N39: =SUMIF('No laborales'!$A$5:$A$12,A39,'No laborales'!$C$5:$C$12) -> 210 | O39: =M39+N39 -> 842 | R39: =IF(P39="","",O39*P39) | S39: =IF(Q39="","",O39*Q39) | T39: =IF(P39="","",(R39+4*O39+S39)/6) | U39: =IF(P39="","",(S39-R39)/6) | V39: =IF(P39="",O39,ROUND(T39,0)) -> 842
A40: EDT-1.8.04 | B40: 1.8 Despliegue y transición | C40: Go-live y estabilización | D40: 8 | E40: 8 | G40: 64 | H40: 64 | I40: 64 | L40: =SUM(D40:K40) -> 208 | M40: =ROUND(SUMPRODUCT(D40:K40,$D$4:$K$4),0) -> 4112 | N40: =SUMIF('No laborales'!$A$5:$A$12,A40,'No laborales'!$C$5:$C$12) -> 500 | O40: =M40+N40 -> 4612 | R40: =IF(P40="","",O40*P40) | S40: =IF(Q40="","",O40*Q40) | T40: =IF(P40="","",(R40+4*O40+S40)/6) | U40: =IF(P40="","",(S40-R40)/6) | V40: =IF(P40="",O40,ROUND(T40,0)) -> 4612
A41: EDT-1.8.05 | B41: 1.8 Despliegue y transición | C41: Transferencia a la operación | D41: 16 | L41: =SUM(D41:K41) -> 16 | M41: =ROUND(SUMPRODUCT(D41:K41,$D$4:$K$4),0) -> 480 | N41: =SUMIF('No laborales'!$A$5:$A$12,A41,'No laborales'!$C$5:$C$12) -> 0 | O41: =M41+N41 -> 480 | R41: =IF(P41="","",O41*P41) | S41: =IF(Q41="","",O41*Q41) | T41: =IF(P41="","",(R41+4*O41+S41)/6) | U41: =IF(P41="","",(S41-R41)/6) | V41: =IF(P41="",O41,ROUND(T41,0)) -> 480
...

Sheet Riesgos
A1: Reserva de contingencia por riesgos identificados
A2: Valor monetario esperado: VME = probabilidad × impacto. Contingencia = Σ VME.
A4: ID | B4: Riesgo | C4: Probabilidad | D4: Impacto (S/) | E4: VME (S/)
A5: R1 | B5: Datos del registro incompletos o de baja calidad | C5: 0.4 | D5: 2000 | E5: =C5*D5 -> 800
A6: R2 | B6: El modelo no alcanza la meta (ROC-AUC ≥ 0,80, recall ≥ 0,60) | C6: 0.3 | D6: 2500 | E6: =C6*D6 -> 750
A7: R3 | B7: Retraso en la integración con el Excel del spa | C7: 0.25 | D7: 1500 | E7: =C7*D7 -> 375
A8: R4 | B8: Baja adopción del personal: capacitación adicional | C8: 0.35 | D8: 1200 | E8: =C8*D8 -> 420
A9: R5 | B9: Falla de la PC o pérdida de datos durante el piloto | C9: 0.1 | D9: 1800 | E9: =C9*D9 -> 180
A10: Reserva de contingencia | E10: =SUM(E5:E9) -> 2525
A12: Probabilidad e impacto: estimación del equipo en el registro de riesgos (juicio de expertos).

Sheet Presupuesto
A1: Presupuesto del proyecto
A2: Línea base de costos = Σ paquetes + reserva de contingencia. Presupuesto = línea base + reserva de gestión.
A4: Entregable (nivel 2 de la EDT) | B4: Costo estimado (S/) | C4: % del total de paquetes
A5: 1.1 Gestión del proyecto | B5: =SUMIF(Paquetes!$B$6:$B$41,A5,Paquetes!$V$6:$V$41) -> 9048 | C5: =IF($B$13=0,0,B5/$B$13) -> 0.24103575
A6: 1.2 Análisis y diseño | B6: =SUMIF(Paquetes!$B$6:$B$41,A6,Paquetes!$V$6:$V$41) -> 3304 | C6: =IF($B$13=0,0,B6/$B$13) -> 0.088017476
A7: 1.3 Datos y modelo predictivo | B7: =SUMIF(Paquetes!$B$6:$B$41,A7,Paquetes!$V$6:$V$41) -> 4905 | C7: =IF($B$13=0,0,B7/$B$13) -> 0.13066759
A8: 1.4 Backend e integración | B8: =SUMIF(Paquetes!$B$6:$B$41,A8,Paquetes!$V$6:$V$41) -> 3575 | C8: =IF($B$13=0,0,B8/$B$13) -> 0.095236827
A9: 1.5 Aplicación web CRM | B9: =SUMIF(Paquetes!$B$6:$B$41,A9,Paquetes!$V$6:$V$41) -> 2880 | C9: =IF($B$13=0,0,B9/$B$13) -> 0.076722255
A10: 1.6 Módulo de retención | B10: =SUMIF(Paquetes!$B$6:$B$41,A10,Paquetes!$V$6:$V$41) -> 3184 | C10: =IF($B$13=0,0,B10/$B$13) -> 0.084820715
A11: 1.7 Pruebas y calidad | B11: =SUMIF(Paquetes!$B$6:$B$41,A11,Paquetes!$V$6:$V$41) -> 2544 | C11: =IF($B$13=0,0,B11/$B$13) -> 0.067771325
A12: 1.8 Despliegue y transición | B12: =SUMIF(Paquetes!$B$6:$B$41,A12,Paquetes!$V$6:$V$41) -> 8098 | C12: =IF($B$13=0,0,B12/$B$13) -> 0.21572806
A13: Costo de los paquetes de trabajo | B13: =SUM(B5:B12) -> 37538 | C13: =SUM(C5:C12) -> 1
A14: + Reserva de contingencia (riesgos identificados) | B14: =Riesgos!E10 -> 2525
A15: Línea base de costos (BAC) | B15: =B13+B14 -> 40063
A16: Reserva de gestión (% de la línea base) | B16: 0.05
A17: + Reserva de gestión (S/) | B17: =ROUND(B15*B16,0) -> 2003
A18: PRESUPUESTO TOTAL DEL PROYECTO | B18: =B15+B17 -> 42066
A20: Presupuesto autorizado en el acta de constitución | B20: 42200
A21: Holgura frente al acta (S/) | B21: =B20-B18 -> 134 | C21: =IF(B21>=0,"Dentro de lo autorizado","Excede lo autorizado") -> Dentro de lo autorizado
A22: Tope con tolerancia del acta (+10 %) | B22: =B20*1.1 -> 46420

Sheet Curva S
A1: Curva S — valor planificado (PV) acumulado por semana
A2: Gasto semanal planificado de los paquetes según el cronograma (15/09/2026 – 15/01/2027). Sin reservas.
A4: Semana | B4: Fin de semana | C4: PV semanal (S/) | D4: PV acumulado (S/) | E4: Línea base BAC (S/) | F4: Presupuesto total (S/)
A5: 1 | B5: 46283 | C5: 1120 | D5: =C5 -> 1120 | E5: =Presupuesto!$B$15 -> 40063 | F5: =Presupuesto!$B$18 -> 42066
A6: 2 | B6: 46290 | C6: 880 | D6: =D5+C6 -> 2000 | E6: =Presupuesto!$B$15 -> 40063 | F6: =Presupuesto!$B$18 -> 42066
A7: 3 | B7: 46297 | C7: 2912 | D7: =D6+C7 -> 4912 | E7: =Presupuesto!$B$15 -> 40063 | F7: =Presupuesto!$B$18 -> 42066
A8: 4 | B8: 46304 | C8: 2024 | D8: =D7+C8 -> 6936 | E8: =Presupuesto!$B$15 -> 40063 | F8: =Presupuesto!$B$18 -> 42066
A9: 5 | B9: 46311 | C9: 2861 | D9: =D8+C9 -> 9797 | E9: =Presupuesto!$B$15 -> 40063 | F9: =Presupuesto!$B$18 -> 42066
A10: 6 | B10: 46318 | C10: 2385 | D10: =D9+C10 -> 12182 | E10: =Presupuesto!$B$15 -> 40063 | F10: =Presupuesto!$B$18 -> 42066
A11: 7 | B11: 46325 | C11: 3299 | D11: =D10+C11 -> 15481 | E11: =Presupuesto!$B$15 -> 40063 | F11: =Presupuesto!$B$18 -> 42066
A12: 8 | B12: 46332 | C12: 2495 | D12: =D11+C12 -> 17976 | E12: =Presupuesto!$B$15 -> 40063 | F12: =Presupuesto!$B$18 -> 42066
A13: 9 | B13: 46339 | C13: 2373 | D13: =D12+C13 -> 20349 | E13: =Presupuesto!$B$15 -> 40063 | F13: =Presupuesto!$B$18 -> 42066
A14: 10 | B14: 46346 | C14: 2275 | D14: =D13+C14 -> 22624 | E14: =Presupuesto!$B$15 -> 40063 | F14: =Presupuesto!$B$18 -> 42066
A15: 11 | B15: 46353 | C15: 1408 | D15: =D14+C15 -> 24032 | E15: =Presupuesto!$B$15 -> 40063 | F15: =Presupuesto!$B$18 -> 42066
A16: 12 | B16: 46360 | C16: 1664 | D16: =D15+C16 -> 25696 | E16: =Presupuesto!$B$15 -> 40063 | F16: =Presupuesto!$B$18 -> 42066
A17: 13 | B17: 46367 | C17: 1012 | D17: =D16+C17 -> 26708 | E17: =Presupuesto!$B$15 -> 40063 | F17: =Presupuesto!$B$18 -> 42066
... A22: 18 | B22: 46402 | C22: 1200 | D22: =D21+C22 -> 37538 | E22: =Presupuesto!$B$15 -> 40063 | F22: =Presupuesto!$B$18 -> 42066
A23: Total | C23: =SUM(C5:C22) -> 37538 | D23: =IF(ROUND(C23-Paquetes!V42,0)=0,"Cuadra con paquetes","Revisar") -> Cuadra con paquetes
A25: PV semanal: distribución diaria del costo de cada actividad del cronograma (los gastos no laborales se cargan al cierre de su paquete).

Sheet Valor ganado
A1: Gestión del valor ganado (EVM) — ejemplo al corte del hito H2
A2: Ejemplo ilustrativo para el control de costos. En la ejecución real, EV y AC salen del avance y la contabilidad.
A4: Indicador | B4: Valor | C4: Fórmula / interpretación
A5: Fecha de corte | B5: 46332 | C5: Fecha de medición (hito H2)
A6: BAC — presupuesto hasta la conclusión | B6: =Presupuesto!B15 -> 40063 | C6: Línea base de costos
A7: PV — valor planificado | B7: =INDEX('Curva S'!D5:D22,MATCH(B5,'Curva S'!B5:B22,0)) -> 17976 | C7: PV acumulado de la curva S a la fecha de corte
A8: % del PV realmente completado | B8: 0.94 | C8: Supuesto del ejemplo: se completó el 94 % de lo planificado
A9: EV — valor ganado | B9: =ROUND(B7*B8,0) -> 16897 | C9: EV = % completado × valor planificado
A10: Sobrecosto observado (AC / EV) | B10: 1.06 | C10: Supuesto del ejemplo: se gastó 6 % más de lo ganado
A11: AC — costo real | B11: =ROUND(B9*B10,0) -> 17911 | C11: Costo real incurrido a la fecha
A12: CV — variación del costo | B12: =B9-B11 -> -1014 | C12: CV = EV − AC (negativo = sobrecosto)
A13: SV — variación del cronograma | B13: =B9-B7 -> -1079 | C13: SV = EV − PV (negativo = atraso)
A14: CPI — índice de desempeño del costo | B14: =B9/B11 -> 0.94338675 | C14: CPI = EV / AC (< 1 = sobrecosto)
A15: SPI — índice de desempeño del cronograma | B15: =B9/B7 -> 0.93997552 | C15: SPI = EV / PV (< 1 = atraso)
A16: EAC (CPI típico) | B16: =B6/B14 -> 42467.207 | C16: EAC = BAC / CPI
A17: EAC (variación atípica) | B17: =B11+(B6-B9) -> 41077 | C17: EAC = AC + (BAC − EV)
A18: EAC (CPI y SPI) | B18: =B11+(B6-B9)/(B14*B15) -> 44035.304 | C18: EAC = AC + (BAC − EV) / (CPI × SPI)
A19: ETC — estimación hasta concluir | B19: =B16-B11 -> 24556.207 | C19: ETC = EAC − AC
A20: VAC — variación a la conclusión | B20: =B6-B16 -> -2404.2068 | C20: VAC = BAC − EAC
A21: TCPI — índice de desempeño por completar | B21: =(B6-B9)/(B6-B11) -> 1.0457746 | C21: TCPI = (BAC − EV) / (BAC − AC)
A23: Lectura: | B23: =IF(B14<1,"Sobrecosto: ","Dentro del costo: ")&"CPI "&TEXT(B14,"0.00")&" · "&IF(B15<1,"Atraso: ","A tiempo: ")&"SPI "&TEXT(B15,"0.00") -> Sobrecosto: CPI 0.94 · Atraso: SPI 0.94

Sheet Viabilidad
A1: Viabilidad económica de la inversión
A2: Compara el presupuesto con el beneficio esperado por la recuperación de clientes en riesgo.
A4: Concepto | B4: Valor | C4: Fórmula / fuente
A5: Clientes en riesgo de abandono por año | B5: 216 | C5: Dato del análisis de la cartera (contexto del proyecto)
A6: Tasa de recuperación esperada | B6: 0.15 | C6: Supuesto conservador del equipo
A7: Clientes recuperados por año | B7: =ROUND(B5*B6,0) -> 32 | C7: Clientes en riesgo × tasa de recuperación
A8: Ingreso anual por cliente (S/) | B8: 750 | C8: Ticket promedio anual por cliente (supuesto)
A9: Beneficio bruto anual (S/) | B9: =B7*B8 -> 24000 | C9: Clientes recuperados × ingreso por cliente
A10: Costo anual de operación del CRM (S/) | B10: 3600 | C10: Hosting, mantenimiento y soporte (supuesto)
A11: Beneficio neto anual (S/) | B11: =B9-B10 -> 20400 | C11: Beneficio bruto − costo de operación
A12: Tasa de descuento | B12: 0.1 | C12: Costo de oportunidad del capital (supuesto)
A13: Inversión: presupuesto total (S/) | B13: =Presupuesto!B18 -> 42066 | C13: Presupuesto del proyecto
A14: VAN a 3 años (S/) | B14: =-B13+NPV(B12,B11,B11,B11) -> 8665.7806 | C14: VAN = −Inversión + Σ BN / (1 + i)^t, t = 1..3
A15: VAN a 5 años (S/) | B15: =-B13+NPV(B12,B11,B11,B11,B11,B11) -> 35266.05 | C15: VAN = −Inversión + Σ BN / (1 + i)^t, t = 1..5
A16: ROI a 5 años | B16: =(B11*5-B13)/B13 -> 1.4247611 | C16: ROI = (Σ beneficios netos − inversión) / inversión
A17: Periodo de recuperación (años) | B17: =B13/B11 -> 2.0620588 | C17: Inversión / beneficio neto anual
A18: Desembolso real del spa (S/) | B18: ='No laborales'!C13+Presupuesto!B14+Presupuesto!B17 -> 6738 | C18: No laborales + contingencia + reserva de gestión (las horas del equipo se valorizan pero no se pagan)
A19: Recuperación del desembolso real (meses) | B19: =B18/(B11/12) -> 3.9635294 | C19: Desembolso real / beneficio neto mensual
